Workbook
Name _D_DG1: 'V1'!$C$14:$I$19
Name _IGNORE_SHEET_: 'MX-GRID 사용 안내'!$B$20
Name _VIEW_RANGE_1: 'V1'!$A$2:$J$21
Name VS_DAY: 'P1'!$C$8

Sheet V1
D3: 001 | E3: 002 | F3: 003 | G3: 004 | H3: 005 | I3: 006
C6: 기준환율 | D6: USD | E6: JPY | F6: EUR | G6: CNY | H6: INR | I6: MXN
D7: =IFERROR(INDEX(D_기준환율!$D:$D, MATCH(LEFT(VS_DAY,6)&'V1'!D$3, D_기준환율!$E:$E, 0)), "") -> 1332 | E7: =IFERROR(INDEX(D_기준환율!$D:$D, MATCH(LEFT(VS_DAY,6)&'V1'!E$3, D_기준환율!$E:$E, 0)), "") -> 11 | F7: =IFERROR(INDEX(D_기준환율!$D:$D, MATCH(LEFT(VS_DAY,6)&'V1'!F$3, D_기준환율!$E:$E, 0)), "") -> 1545 | G7: =IFERROR(INDEX(D_기준환율!$D:$D, MATCH(LEFT(VS_DAY,6)&'V1'!G$3, D_기준환율!$E:$E, 0)), "") -> 83 | H7: =IFERROR(INDEX(D_기준환율!$D:$D, MATCH(LEFT(VS_DAY,6)&'V1'!H$3, D_기준환율!$E:$E, 0)), "") -> 16 | I7: =IFERROR(INDEX(D_기준환율!$D:$D, MATCH(LEFT(VS_DAY,6)&'V1'!I$3, D_기준환율!$E:$E, 0)), "") -> 72
C8: =VALUE(MID(VS_DAY,5,2)) & "월" & VALUE(RIGHT(VS_DAY, 2)) & "일 마감기준" -> 7월3일 마감기준 | D8: =IFERROR(INDEX(D_환율!$D:$D, MATCH(VS_DAY&'V1'!D$3, D_환율!$E:$E, 0)), "") -> 1400 | E8: =IFERROR(INDEX(D_환율!$D:$D, MATCH(VS_DAY&'V1'!E$3, D_환율!$E:$E, 0)), "") -> 8 | F8: =IFERROR(INDEX(D_환율!$D:$D, MATCH(VS_DAY&'V1'!F$3, D_환율!$E:$E, 0)), "") -> 1588 | G8: =IFERROR(INDEX(D_환율!$D:$D, MATCH(VS_DAY&'V1'!G$3, D_환율!$E:$E, 0)), "") -> 80 | H8: =IFERROR(INDEX(D_환율!$D:$D, MATCH(VS_DAY&'V1'!H$3, D_환율!$E:$E, 0)), "") -> 17 | I8: =IFERROR(INDEX(D_환율!$D:$D, MATCH(VS_DAY&'V1'!I$3, D_환율!$E:$E, 0)), "") -> 67
C13: =LEFT(VS_DAY,4) & "년 누계기준" -> 2025년 누계기준
C14: 구분 | D14: 통화별 매출 | E14: KRW 매출 | F14: 환율(원) | G14: 매출환차 | H14: 이익률 | I14: BEP
B15: 007 | C15: KRW | D15: =IFERROR(SUMIFS(D_매출!D:D, D_매출!F:F, TRUE, D_매출!B:B, 'V1'!$B15), "") -> 1190 | E15: =D15 -> 1190 | F15: 1 | G15: =0 -> 0 | H15: =IFERROR(SUMIFS(D_매출!E:E, D_매출!F:F, TRUE, D_매출!B:B, 'V1'!$B15)/SUMIFS(D_매출!D:D, D_매출!F:F, TRUE, D_매출!B:B, 'V1'!$B15), "") -> 0.55462185 | I15: =IFERROR(INDEX(D_BEP!D:D, MATCH(LEFT(VS_DAY,6)&'V1'!B15, D_BEP!E:E, 0)), "") -> 21736
B16: 002 | C16: JPY | D16: =IFERROR(SUMIFS(D_매출!D:D, D_매출!F:F, TRUE, D_매출!B:B, 'V1'!$B16), "") -> 581 | E16: =D16*E7 -> 6391 | F16: =E8 -> 8 | G16: =IFERROR($D16*(E$8-E$7), "") -> -1743 | H16: =IFERROR(SUMIFS(D_매출!E:E, D_매출!F:F, TRUE, D_매출!B:B, 'V1'!$B16)/SUMIFS(D_매출!D:D, D_매출!F:F, TRUE, D_매출!B:B, 'V1'!$B16), "") -> 1.5783133 | I16: =IFERROR(INDEX(D_BEP!D:D, MATCH(LEFT(VS_DAY,6)&'V1'!B16, D_BEP!E:E, 0)), "") -> 10000
B17: 001 | C17: USD | D17: =IFERROR(SUMIFS(D_매출!D:D, D_매출!F:F, TRUE, D_매출!B:B, 'V1'!$B17), "") -> 127 | E17: =D17*D7 -> 169164 | F17: =D8 -> 1400 | G17: =IFERROR($D17*(D$8-D$7), "") -> 8636 | H17: =IFERROR(SUMIFS(D_매출!E:E, D_매출!F:F, TRUE, D_매출!B:B, 'V1'!$B17)/SUMIFS(D_매출!D:D, D_매출!F:F, TRUE, D_매출!B:B, 'V1'!$B17), "") -> 0.45669291 | I17: =IFERROR(INDEX(D_BEP!D:D, MATCH(LEFT(VS_DAY,6)&'V1'!B17, D_BEP!E:E, 0)), "") -> 150000
B18: 003 | C18: EUR | D18: =IFERROR(SUMIFS(D_매출!D:D, D_매출!F:F, TRUE, D_매출!B:B, 'V1'!$B18), "") -> 117 | E18: =D18*F7 -> 180765 | F18: =F8 -> 1588 | G18: =IFERROR($D18*(F$8-F$7), "") -> 5031 | H18: =IFERROR(SUMIFS(D_매출!E:E, D_매출!F:F, TRUE, D_매출!B:B, 'V1'!$B18)/SUMIFS(D_매출!D:D, D_매출!F:F, TRUE, D_매출!B:B, 'V1'!$B18), "") -> 0.61538462 | I18: =IFERROR(INDEX(D_BEP!D:D, MATCH(LEFT(VS_DAY,6)&'V1'!B18, D_BEP!E:E, 0)), "") -> 130000
B19: 004 | C19: CNY | D19: =IFERROR(SUMIFS(D_매출!D:D, D_매출!F:F, TRUE, D_매출!B:B, 'V1'!$B19), "") -> 715 | E19: =D19*G7 -> 59345 | F19: =G8 -> 80 | G19: =IFERROR($D18*(G$8-G$7), "") -> -351 | H19: =IFERROR(SUMIFS(D_매출!E:E, D_매출!F:F, TRUE, D_매출!B:B, 'V1'!$B19)/SUMIFS(D_매출!D:D, D_매출!F:F, TRUE, D_매출!B:B, 'V1'!$B19), "") -> 1.0251748 | I19: =IFERROR(INDEX(D_BEP!D:D, MATCH(LEFT(VS_DAY,6)&'V1'!B19, D_BEP!E:E, 0)), "") -> 50000
C20: 총합계 | D20: =IFERROR(SUM(D15:D19), "") -> 2730 | E20: =IFERROR(SUM(E15:E19), "") -> 416855 | F20: - | G20: =IFERROR(SUM(G15:G19), "") -> 11573 | H20: =IFERROR(SUMIFS(D_매출!E:E, D_매출!F:F, TRUE)/SUMIFS(D_매출!D:D, D_매출!F:F, TRUE), "") -> 0.89947322 | I20: =IFERROR(SUM(I15:I19), "") -> 361736

Sheet T_차트
B2: 기준년월 | C2: 기준환율 매출 | D2: 기준환율 이익률 | E2: 실적환율 매출 | F2: 실적환율 이익률
B3: 1월 | C3: =RANDBETWEEN(1000,5000) -> 2579 | D3: =RAND()*(1.5-0.8)+0.8 -> 1.0334964 | E3: =RANDBETWEEN(1000,5000) -> 2971 | F3: =RAND()*(1.5-0.8)+0.8 -> 0.9854459
B4: 2월 | C4: =RANDBETWEEN(1000,5000) -> 3931 | D4: =RAND()*(1.5-0.8)+0.8 -> 1.2068173 | E4: =RANDBETWEEN(1000,5000) -> 4197 | F4: =RAND()*(1.5-0.8)+0.8 -> 0.82350989
B5: 3월 | C5: =RANDBETWEEN(1000,5000) -> 3127 | D5: =RAND()*(1.5-0.8)+0.8 -> 1.2898413 | E5: =RANDBETWEEN(1000,5000) -> 3184 | F5: =RAND()*(1.5-0.8)+0.8 -> 0.89707477
B6: 4월 | C6: =RANDBETWEEN(1000,5000) -> 2879 | D6: =RAND()*(1.5-0.8)+0.8 -> 1.4806892 | E6: =RANDBETWEEN(1000,5000) -> 3324 | F6: =RAND()*(1.5-0.8)+0.8 -> 1.2114908
B7: 5월 | C7: =RANDBETWEEN(1000,5000) -> 4280 | D7: =RAND()*(1.5-0.8)+0.8 -> 1.3648774 | E7: =RANDBETWEEN(1000,5000) -> 1325 | F7: =RAND()*(1.5-0.8)+0.8 -> 1.1819297
B8: 6월 | C8: =RANDBETWEEN(1000,5000) -> 1190 | D8: =RAND()*(1.5-0.8)+0.8 -> 1.0909997 | E8: =RANDBETWEEN(1000,5000) -> 1406 | F8: =RAND()*(1.5-0.8)+0.8 -> 1.2178875
B9: 7월 | C9: =RANDBETWEEN(1000,5000) -> 1408 | D9: =RAND()*(1.5-0.8)+0.8 -> 1.4267761 | E9: =RANDBETWEEN(1000,5000) -> 2125 | F9: =RAND()*(1.5-0.8)+0.8 -> 0.83619373

Sheet D_BEP
A1: 기준년월 | B1: 국가코드 | C1: 국가명 | D1: BEP | E1: 기준년월&국가코드
A2: 202507 | B2: 001 | C2: USD | D2: 150000 | E2: =A2&B2 -> 202507001
A3: 202507 | B3: 002 | C3: JPY | D3: 10000 | E3: =A3&B3 -> 202507002
A4: 202507 | B4: 003 | C4: EUR | D4: 130000 | E4: =A4&B4 -> 202507003
A5: 202507 | B5: 004 | C5: CNY | D5: 50000 | E5: =A5&B5 -> 202507004
A6: 202507 | B6: 005 | C6: INR | D6: 35239 | E6: =A6&B6 -> 202507005
A7: 202507 | B7: 006 | C7: MXN | D7: 23927 | E7: =A7&B7 -> 202507006
A8: 202507 | B8: 007 | C8: KRW | D8: 21736 | E8: =A8&B8 -> 202507007

Sheet D_매출
A1: 기준년월 | B1: 국가코드 | C1: 국가명 | D1: 매출 | E1: 이익 | F1: 기준월 이내
A2: 20250701 | B2: 001 | C2: USD | D2: =RANDBETWEEN(10,50) -> 38 | E2: =RANDBETWEEN(10,50) -> 16 | F2: =A2<=VS_DAY -> TRUE
A3: 20250701 | B3: 002 | C3: JPY | D3: =RANDBETWEEN(100,500) -> 214 | E3: =RANDBETWEEN(100,500) -> 409 | F3: =A3<=VS_DAY -> TRUE
A4: 20250701 | B4: 003 | C4: EUR | D4: =RANDBETWEEN(10,50) -> 33 | E4: =RANDBETWEEN(10,50) -> 14 | F4: =A4<=VS_DAY -> TRUE
A5: 20250701 | B5: 004 | C5: CNY | D5: =RANDBETWEEN(100,500) -> 127 | E5: =RANDBETWEEN(100,500) -> 429 | F5: =A5<=VS_DAY -> TRUE
A6: 20250701 | B6: 005 | C6: INR | D6: =RANDBETWEEN(100,500) -> 201 | E6: =RANDBETWEEN(100,500) -> 130 | F6: =A6<=VS_DAY -> TRUE
A7: 20250701 | B7: 006 | C7: MXN | D7: =RANDBETWEEN(100,500) -> 406 | E7: =RANDBETWEEN(100,500) -> 267 | F7: =A7<=VS_DAY -> TRUE
A8: 20250701 | B8: 007 | C8: KRW | D8: =RANDBETWEEN(100,500) -> 428 | E8: =RANDBETWEEN(100,500) -> 291 | F8: =A8<=VS_DAY -> TRUE
A9: 20250702 | B9: 001 | C9: USD | D9: =RANDBETWEEN(10,50) -> 39 | E9: =RANDBETWEEN(10,50) -> 19 | F9: =A9<=VS_DAY -> TRUE
A10: 20250702 | B10: 002 | C10: JPY | D10: =RANDBETWEEN(100,500) -> 205 | E10: =RANDBETWEEN(100,500) -> 255 | F10: =A10<=VS_DAY -> TRUE
A11: 20250702 | B11: 003 | C11: EUR | D11: =RANDBETWEEN(10,50) -> 46 | E11: =RANDBETWEEN(10,50) -> 17 | F11: =A11<=VS_DAY -> TRUE
A12: 20250702 | B12: 004 | C12: CNY | D12: =RANDBETWEEN(100,500) -> 214 | E12: =RANDBETWEEN(100,500) -> 166 | F12: =A12<=VS_DAY -> TRUE
A13: 20250702 | B13: 005 | C13: INR | D13: =RANDBETWEEN(100,500) -> 363 | E13: =RANDBETWEEN(100,500) -> 379 | F13: =A13<=VS_DAY -> TRUE
A14: 20250702 | B14: 006 | C14: MXN | D14: =RANDBETWEEN(100,500) -> 302 | E14: =RANDBETWEEN(100,500) -> 398 | F14: =A14<=VS_DAY -> TRUE
A15: 20250702 | B15: 007 | C15: KRW | D15: =RANDBETWEEN(100,500) -> 310 | E15: =RANDBETWEEN(100,500) -> 123 | F15: =A15<=VS_DAY -> TRUE
A16: 20250703 | B16: 001 | C16: USD | D16: =RANDBETWEEN(10,50) -> 50 | E16: =RANDBETWEEN(10,50) -> 23 | F16: =A16<=VS_DAY -> TRUE
A17: 20250703 | B17: 002 | C17: JPY | D17: =RANDBETWEEN(100,500) -> 162 | E17: =RANDBETWEEN(100,500) -> 253 | F17: =A17<=VS_DAY -> TRUE
A18: 20250703 | B18: 003 | C18: EUR | D18: =RANDBETWEEN(10,50) -> 38 | E18: =RANDBETWEEN(10,50) -> 41 | F18: =A18<=VS_DAY -> TRUE
A19: 20250703 | B19: 004 | C19: CNY | D19: =RANDBETWEEN(100,500) -> 374 | E19: =RANDBETWEEN(100,500) -> 138 | F19: =A19<=VS_DAY -> TRUE
A20: 20250703 | B20: 005 | C20: INR | D20: =RANDBETWEEN(100,500) -> 149 | E20: =RANDBETWEEN(100,500) -> 117 | F20: =A20<=VS_DAY -> TRUE
A21: 20250703 | B21: 006 | C21: MXN | D21: =RANDBETWEEN(100,500) -> 405 | E21: =RANDBETWEEN(100,500) -> 367 | F21: =A21<=VS_DAY -> TRUE
A22: 20250703 | B22: 007 | C22: KRW | D22: =RANDBETWEEN(100,500) -> 452 | E22: =RANDBETWEEN(100,500) -> 246 | F22: =A22<=VS_DAY -> TRUE
A23: 20250704 | B23: 001 | C23: USD | D23: =RANDBETWEEN(10,50) -> 11 | E23: =RANDBETWEEN(10,50) -> 21 | F23: =A23<=VS_DAY -> FALSE
A24: 20250704 | B24: 002 | C24: JPY | D24: =RANDBETWEEN(100,500) -> 104 | E24: =RANDBETWEEN(100,500) -> 483 | F24: =A24<=VS_DAY -> FALSE
A25: 20250704 | B25: 003 | C25: EUR | D25: =RANDBETWEEN(10,50) -> 47 | E25: =RANDBETWEEN(10,50) -> 10 | F25: =A25<=VS_DAY -> FALSE
A26: 20250704 | B26: 004 | C26: CNY | D26: =RANDBETWEEN(100,500) -> 235 | E26: =RANDBETWEEN(100,500) -> 126 | F26: =A26<=VS_DAY -> FALSE
A27: 20250704 | B27: 005 | C27: INR | D27: =RANDBETWEEN(100,500) -> 293 | E27: =RANDBETWEEN(100,500) -> 318 | F27: =A27<=VS_DAY -> FALSE
A28: 20250704 | B28: 006 | C28: MXN | D28: =RANDBETWEEN(100,500) -> 229 | E28: =RANDBETWEEN(100,500) -> 118 | F28: =A28<=VS_DAY -> FALSE
A29: 20250704 | B29: 007 | C29: KRW | D29: =RANDBETWEEN(100,500) -> 416 | E29: =RANDBETWEEN(100,500) -> 324 | F29: =A29<=VS_DAY -> FALSE
A30: 20250705 | B30: 001 | C30: USD | D30: =RANDBETWEEN(10,50) -> 28 | E30: =RANDBETWEEN(10,50) -> 20 | F30: =A30<=VS_DAY -> FALSE
A31: 20250705 | B31: 002 | C31: JPY | D31: =RANDBETWEEN(100,500) -> 277 | E31: =RANDBETWEEN(100,500) -> 151 | F31: =A31<=VS_DAY -> FALSE
A32: 20250705 | B32: 003 | C32: EUR | D32: =RANDBETWEEN(10,50) -> 24 | E32: =RANDBETWEEN(10,50) -> 12 | F32: =A32<=VS_DAY -> FALSE
A33: 20250705 | B33: 004 | C33: CNY | D33: =RANDBETWEEN(100,500) -> 191 | E33: =RANDBETWEEN(100,500) -> 356 | F33: =A33<=VS_DAY -> FALSE
A34: 20250705 | B34: 005 | C34: INR | D34: =RANDBETWEEN(100,500) -> 100 | E34: =RANDBETWEEN(100,500) -> 446 | F34: =A34<=VS_DAY -> FALSE
A35: 20250705 | B35: 006 | C35: MXN | D35: =RANDBETWEEN(100,500) -> 165 | E35: =RANDBETWEEN(100,500) -> 224 | F35: =A35<=VS_DAY -> FALSE
A36: 20250705 | B36: 007 | C36: KRW | D36: =RANDBETWEEN(100,500) -> 143 | E36: =RANDBETWEEN(100,500) -> 469 | F36: =A36<=VS_DAY -> FALSE
A37: 20250706 | B37: 001 | C37: USD | D37: =RANDBETWEEN(10,50) -> 11 | E37: =RANDBETWEEN(10,50) -> 43 | F37: =A37<=VS_DAY -> FALSE
A38: 20250706 | B38: 002 | C38: JPY | D38: =RANDBETWEEN(100,500) -> 483 | E38: =RANDBETWEEN(100,500) -> 311 | F38: =A38<=VS_DAY -> FALSE
A39: 20250706 | B39: 003 | C39: EUR | D39: =RANDBETWEEN(10,50) -> 12 | E39: =RANDBETWEEN(10,50) -> 31 | F39: =A39<=VS_DAY -> FALSE
A40: 20250706 | B40: 004 | C40: CNY | D40: =RANDBETWEEN(100,500) -> 108 | E40: =RANDBETWEEN(100,500) -> 286 | F40: =A40<=VS_DAY -> FALSE
...

Sheet D_환율
A1: 기준일자 | B1: 국가코드 | C1: 국가명 | D1: 환율 | E1: 년월&국가코드
A2: 20250701 | B2: 001 | C2: USD | D2: =RANDBETWEEN(1300, 1450) -> 1345 | E2: =A2&B2 -> 20250701001
A3: 20250701 | B3: 002 | C3: JPY | D3: =RANDBETWEEN(8,11) -> 9 | E3: =A3&B3 -> 20250701002
A4: 20250701 | B4: 003 | C4: EUR | D4: =RANDBETWEEN(1400, 1600) -> 1471 | E4: =A4&B4 -> 20250701003
A5: 20250701 | B5: 004 | C5: CNY | D5: =RANDBETWEEN(75,85) -> 84 | E5: =A5&B5 -> 20250701004
A6: 20250701 | B6: 005 | C6: INR | D6: =RANDBETWEEN(14,17) -> 14 | E6: =A6&B6 -> 20250701005
A7: 20250701 | B7: 006 | C7: MXN | D7: =RANDBETWEEN(65,75) -> 68 | E7: =A7&B7 -> 20250701006
A8: 20250702 | B8: 001 | C8: USD | D8: =RANDBETWEEN(1300, 1450) -> 1345 | E8: =A8&B8 -> 20250702001
A9: 20250702 | B9: 002 | C9: JPY | D9: =RANDBETWEEN(8,11) -> 9 | E9: =A9&B9 -> 20250702002
A10: 20250702 | B10: 003 | C10: EUR | D10: =RANDBETWEEN(1400, 1600) -> 1423 | E10: =A10&B10 -> 20250702003
A11: 20250702 | B11: 004 | C11: CNY | D11: =RANDBETWEEN(75,85) -> 76 | E11: =A11&B11 -> 20250702004
A12: 20250702 | B12: 005 | C12: INR | D12: =RANDBETWEEN(14,17) -> 17 | E12: =A12&B12 -> 20250702005
A13: 20250702 | B13: 006 | C13: MXN | D13: =RANDBETWEEN(65,75) -> 66 | E13: =A13&B13 -> 20250702006
A14: 20250703 | B14: 001 | C14: USD | D14: =RANDBETWEEN(1300, 1450) -> 1400 | E14: =A14&B14 -> 20250703001
A15: 20250703 | B15: 002 | C15: JPY | D15: =RANDBETWEEN(8,11) -> 8 | E15: =A15&B15 -> 20250703002
A16: 20250703 | B16: 003 | C16: EUR | D16: =RANDBETWEEN(1400, 1600) -> 1588 | E16: =A16&B16 -> 20250703003
A17: 20250703 | B17: 004 | C17: CNY | D17: =RANDBETWEEN(75,85) -> 80 | E17: =A17&B17 -> 20250703004
A18: 20250703 | B18: 005 | C18: INR | D18: =RANDBETWEEN(14,17) -> 17 | E18: =A18&B18 -> 20250703005
A19: 20250703 | B19: 006 | C19: MXN | D19: =RANDBETWEEN(65,75) -> 67 | E19: =A19&B19 -> 20250703006
A20: 20250704 | B20: 001 | C20: USD | D20: =RANDBETWEEN(1300, 1450) -> 1406 | E20: =A20&B20 -> 20250704001
A21: 20250704 | B21: 002 | C21: JPY | D21: =RANDBETWEEN(8,11) -> 10 | E21: =A21&B21 -> 20250704002
A22: 20250704 | B22: 003 | C22: EUR | D22: =RANDBETWEEN(1400, 1600) -> 1422 | E22: =A22&B22 -> 20250704003
A23: 20250704 | B23: 004 | C23: CNY | D23: =RANDBETWEEN(75,85) -> 79 | E23: =A23&B23 -> 20250704004
A24: 20250704 | B24: 005 | C24: INR | D24: =RANDBETWEEN(14,17) -> 16 | E24: =A24&B24 -> 20250704005
A25: 20250704 | B25: 006 | C25: MXN | D25: =RANDBETWEEN(65,75) -> 73 | E25: =A25&B25 -> 20250704006
A26: 20250705 | B26: 001 | C26: USD | D26: =RANDBETWEEN(1300, 1450) -> 1302 | E26: =A26&B26 -> 20250705001
A27: 20250705 | B27: 002 | C27: JPY | D27: =RANDBETWEEN(8,11) -> 8 | E27: =A27&B27 -> 20250705002
A28: 20250705 | B28: 003 | C28: EUR | D28: =RANDBETWEEN(1400, 1600) -> 1529 | E28: =A28&B28 -> 20250705003
A29: 20250705 | B29: 004 | C29: CNY | D29: =RANDBETWEEN(75,85) -> 84 | E29: =A29&B29 -> 20250705004
A30: 20250705 | B30: 005 | C30: INR | D30: =RANDBETWEEN(14,17) -> 15 | E30: =A30&B30 -> 20250705005
A31: 20250705 | B31: 006 | C31: MXN | D31: =RANDBETWEEN(65,75) -> 73 | E31: =A31&B31 -> 20250705006
A32: 20250706 | B32: 001 | C32: USD | D32: =RANDBETWEEN(1300, 1450) -> 1387 | E32: =A32&B32 -> 20250706001
A33: 20250706 | B33: 002 | C33: JPY | D33: =RANDBETWEEN(8,11) -> 9 | E33: =A33&B33 -> 20250706002
A34: 20250706 | B34: 003 | C34: EUR | D34: =RANDBETWEEN(1400, 1600) -> 1446 | E34: =A34&B34 -> 20250706003
A35: 20250706 | B35: 004 | C35: CNY | D35: =RANDBETWEEN(75,85) -> 79 | E35: =A35&B35 -> 20250706004
A36: 20250706 | B36: 005 | C36: INR | D36: =RANDBETWEEN(14,17) -> 16 | E36: =A36&B36 -> 20250706005
A37: 20250706 | B37: 006 | C37: MXN | D37: =RANDBETWEEN(65,75) -> 65 | E37: =A37&B37 -> 20250706006
A38: 20250707 | B38: 001 | C38: USD | D38: =RANDBETWEEN(1300, 1450) -> 1360 | E38: =A38&B38 -> 20250707001
A39: 20250707 | B39: 002 | C39: JPY | D39: =RANDBETWEEN(8,11) -> 9 | E39: =A39&B39 -> 20250707002
A40: 20250707 | B40: 003 | C40: EUR | D40: =RANDBETWEEN(1400, 1600) -> 1501 | E40: =A40&B40 -> 20250707003
...

Sheet D_기준환율
A1: 기준년월 | B1: 국가코드 | C1: 국가명 | D1: 기준환율 | E1: 년월&국가코드
A2: 202501 | B2: 001 | C2: USD | D2: =RANDBETWEEN(1300, 1450) -> 1375 | E2: =A2&B2 -> 202501001
A3: 202501 | B3: 002 | C3: JPY | D3: =RANDBETWEEN(8,11) -> 10 | E3: =A3&B3 -> 202501002
A4: 202501 | B4: 003 | C4: EUR | D4: =RANDBETWEEN(1400, 1600) -> 1424 | E4: =A4&B4 -> 202501003
A5: 202501 | B5: 004 | C5: CNY | D5: =RANDBETWEEN(75,85) -> 76 | E5: =A5&B5 -> 202501004
A6: 202501 | B6: 005 | C6: INR | D6: =RANDBETWEEN(14,17) -> 16 | E6: =A6&B6 -> 202501005
A7: 202501 | B7: 006 | C7: MXN | D7: =RANDBETWEEN(65,75) -> 66 | E7: =A7&B7 -> 202501006
A8: 202502 | B8: 001 | C8: USD | D8: =RANDBETWEEN(1300, 1450) -> 1376 | E8: =A8&B8 -> 202502001
A9: 202502 | B9: 002 | C9: JPY | D9: =RANDBETWEEN(8,11) -> 11 | E9: =A9&B9 -> 202502002
A10: 202502 | B10: 003 | C10: EUR | D10: =RANDBETWEEN(1400, 1600) -> 1590 | E10: =A10&B10 -> 202502003
A11: 202502 | B11: 004 | C11: CNY | D11: =RANDBETWEEN(75,85) -> 77 | E11: =A11&B11 -> 202502004
A12: 202502 | B12: 005 | C12: INR | D12: =RANDBETWEEN(14,17) -> 15 | E12: =A12&B12 -> 202502005
A13: 202502 | B13: 006 | C13: MXN | D13: =RANDBETWEEN(65,75) -> 72 | E13: =A13&B13 -> 202502006
A14: 202503 | B14: 001 | C14: USD | D14: =RANDBETWEEN(1300, 1450) -> 1362 | E14: =A14&B14 -> 202503001
A15: 202503 | B15: 002 | C15: JPY | D15: =RANDBETWEEN(8,11) -> 8 | E15: =A15&B15 -> 202503002
A16: 202503 | B16: 003 | C16: EUR | D16: =RANDBETWEEN(1400, 1600) -> 1535 | E16: =A16&B16 -> 202503003
A17: 202503 | B17: 004 | C17: CNY | D17: =RANDBETWEEN(75,85) -> 78 | E17: =A17&B17 -> 202503004
A18: 202503 | B18: 005 | C18: INR | D18: =RANDBETWEEN(14,17) -> 16 | E18: =A18&B18 -> 202503005
A19: 202503 | B19: 006 | C19: MXN | D19: =RANDBETWEEN(65,75) -> 71 | E19: =A19&B19 -> 202503006
A20: 202504 | B20: 001 | C20: USD | D20: =RANDBETWEEN(1300, 1450) -> 1405 | E20: =A20&B20 -> 202504001
A21: 202504 | B21: 002 | C21: JPY | D21: =RANDBETWEEN(8,11) -> 10 | E21: =A21&B21 -> 202504002
A22: 202504 | B22: 003 | C22: EUR | D22: =RANDBETWEEN(1400, 1600) -> 1472 | E22: =A22&B22 -> 202504003
A23: 202504 | B23: 004 | C23: CNY | D23: =RANDBETWEEN(75,85) -> 75 | E23: =A23&B23 -> 202504004
A24: 202504 | B24: 005 | C24: INR | D24: =RANDBETWEEN(14,17) -> 16 | E24: =A24&B24 -> 202504005
A25: 202504 | B25: 006 | C25: MXN | D25: =RANDBETWEEN(65,75) -> 68 | E25: =A25&B25 -> 202504006
A26: 202505 | B26: 001 | C26: USD | D26: =RANDBETWEEN(1300, 1450) -> 1359 | E26: =A26&B26 -> 202505001
A27: 202505 | B27: 002 | C27: JPY | D27: =RANDBETWEEN(8,11) -> 8 | E27: =A27&B27 -> 202505002
A28: 202505 | B28: 003 | C28: EUR | D28: =RANDBETWEEN(1400, 1600) -> 1552 | E28: =A28&B28 -> 202505003
A29: 202505 | B29: 004 | C29: CNY | D29: =RANDBETWEEN(75,85) -> 84 | E29: =A29&B29 -> 202505004
A30: 202505 | B30: 005 | C30: INR | D30: =RANDBETWEEN(14,17) -> 17 | E30: =A30&B30 -> 202505005
A31: 202505 | B31: 006 | C31: MXN | D31: =RANDBETWEEN(65,75) -> 73 | E31: =A31&B31 -> 202505006
A32: 202506 | B32: 001 | C32: USD | D32: =RANDBETWEEN(1300, 1450) -> 1321 | E32: =A32&B32 -> 202506001
A33: 202506 | B33: 002 | C33: JPY | D33: =RANDBETWEEN(8,11) -> 9 | E33: =A33&B33 -> 202506002
A34: 202506 | B34: 003 | C34: EUR | D34: =RANDBETWEEN(1400, 1600) -> 1509 | E34: =A34&B34 -> 202506003
A35: 202506 | B35: 004 | C35: CNY | D35: =RANDBETWEEN(75,85) -> 75 | E35: =A35&B35 -> 202506004
A36: 202506 | B36: 005 | C36: INR | D36: =RANDBETWEEN(14,17) -> 14 | E36: =A36&B36 -> 202506005
A37: 202506 | B37: 006 | C37: MXN | D37: =RANDBETWEEN(65,75) -> 67 | E37: =A37&B37 -> 202506006
A38: 202507 | B38: 001 | C38: USD | D38: =RANDBETWEEN(1300, 1450) -> 1332 | E38: =A38&B38 -> 202507001
A39: 202507 | B39: 002 | C39: JPY | D39: =RANDBETWEEN(8,11) -> 11 | E39: =A39&B39 -> 202507002
A40: 202507 | B40: 003 | C40: EUR | D40: =RANDBETWEEN(1400, 1600) -> 1545 | E40: =A40&B40 -> 202507003
...

Sheet P1
B6: ▣ 변수 목록
B7: 이름 | C7: 이름정의 (변수값) | D7: 초기값 | E7: 설명
B8: VS_DAY | C8: 20250703

Sheet MX-GRID 사용 안내
B2: ■ MX-GRID 예약어(이름 정의) | E2: 작성일 : 2024년 02월 19일 월
B4: MX-GRID는 웹 환경 하에 다양한 동작을 제어하기 위해 엑셀의 이름 정의 규칙을 활용하고 있습니다.
B5: 이름 규칙에 ??는 해당 이름으로 시작하는 모든 항목이 동일한 동작을 한다는 의미 입니다.
B7: 예약어 | C7: 동작 | D7: 비고 | E7: 지원 버전 (DataSet.maf)
B8: _AUTO_SIZE_?? | C8: MX-GRID 크기에 따라 가변적으로 변경될 Column과 Row 영역을 지정합니다. | D8: _AUTO_SIZE_로 시작하는 영역 전부를 이름 정의로 인식합니다. MX-GRID 의 크기가 변경될 경우, 지정된 영역의 크기를 조정합니다. Column과 Row의 최소 크기는 MX-GRID 디자이너에서 저장한 값입니다. MX-GRID의 크기가 증가할 때 셀의 크기를 자동으로 조정합니다.
B9: _RESIZE_AREA_?? | C9: MX-GRID 에서 마우스로 크기를 조정할 영역을 지정합니다. | D9: 범위에 해당하는 MX-GRID 내 셀의 크기를 마우스로 조정할 수 있습니다.
B10: _RESIZE_ROW_?? | C10: MX-GRID 에서 마우스로 높이를 조정할 Row 영역을 지정합니다. | D10: MX-GRID 내 지정된 Row 영역의 높이를 마우스로 조정할 수 있습니다.
B11: _RESIZE_COLUMN_? | C11: MX-GRID 에서 마우스로 너비를 조정할 Column 영역을 지정합니다. | D11: MX-GRID 내 지정된 Column 영역의 너비를 마우스로 조정할 수 있습니다.
B12: _VIEW_AREA_?? | C12: 출력 대상 시트에서 화면의 정보를 읽어야 하는 영역을 지정합니다. | D12: MX-GRID 디자이너의 저장 속도와 서버의 처리 성능이 향상됩니다.
B13: _VIEW_RANGE_?? | C13: 출력 대상 시트에서 화면에 출력할 영역을 지정합니다. | D13: 시트 상의 지정한 영역만 화면으로 출력합니다.
B14: _C_?? | C14: 지정한 컨트롤을 현재 셀의 위치에 배치합니다. | D14: "_C_" + "컨트롤 이름" 의 형식으로 이름 정의를 생성하면 i-AUD 보고서 내 이름이 동일한 컨트롤을 찾아 해당 셀의 위치에 배치합니다. 이때, 컨트롤 이름과 일치하는 내용을 찾지 못할 경우 Textbox를 생성합니다. 이 예약어는 컨트롤의 배치를 MX-GRID 로 제어하는 경우 혹은 입력 폼 생성을 위해 사용합니다.
B15: _D_?? | C15: 데이터 셋의 영역을 지정합니다. 해당 영역의 데이터는 MX-GRID 조회 시 Client로 전달 됩니다. | D15: 컨트롤 생성 규칙에서 헤더 영역을 제외하고 동일한 이름으로 지정할 경우 (eg. _C_VS_CODE , _D_VS_CODE) i-AUD 에서 생성한 컨트롤의 데이터셋을 _D_? 로 지정한 영역의 셀 목록값으로 설정합니다. 보고서 Client Script 에서 MXGRID.getDataTable(name) 을 반환합니다.
B16: _PROTECT_ | C16: 예약어가 포함된 시트를 CRUD 대상으로 지정합니다. | D16: [시트 보호] 기능과 동일하게 동작합니다. 시트 내부에 예약어가 존재할 경우 편집 가능한 셀(셀-셀 서식-보호-잠금 해제)에 CRUD 기능이 적용됩니다. | E16: 7.0.400.13
B17: _PROTECT2_ | C17: 예약어가 포함된 시트를 CRUD 대상으로 지정합니다. | D17: [시트 보호] 기능과 동일하게 동작합니다. 시트 내부에 예약어가 존재할 경우 전체 셀에 CRUD 기능이 적용됩니다. | E17: 7.0.400.13
B18: CRUD_?? | C18: CRUD 데이터 테이블의 시작 위치를 지정합니다. | D18: CRUD 데이터 테이블의 시작 위치를 지정합니다. | E18: 7.0.400.13
B19: _EXPORT_SHEETS_ | C19: 지정한 시트를 Export 대상으로 설정합니다. | D19: Export 대상 시트명을 ","로 분리하여 입력할 경우, 화면 상의 조회 대상 시트와 내보내기 대상 시트를 구분합니다. | E19: 7.0.400.65
B20: _IGNORE_SHEET_ | C20: 예약어가 포함된 시트를 Export 대상에서 제외합니다. | D20: 내부에 예약어가 존재하는 시트를 실제 화면 표시, 내보내기, 연산 등의 작업에서 제외합니다. | E20: 7.0.400.100
B21: _DS_?? | C21: i-AUD 내 데이터소스를 시트에 출력합니다. | D21: i-AUD 보고서 내 저장된 데이터 소스를 실행하여 시트에 출력하며, 해당 데이터가 출력될 시작셀에 이름을 지정합니다. (eg. _DS_Data1, _DS_Data2) | E21: 7.0.500.37
B24: ■ MX-GRID 전용 함수(AUD_xxx) | E24: 작성일 : 2023년 06월 14일 수
B26: MX-GRID는 AUD_xxx 시작하는 전용 함수를 제공하여 화면 상의 특정 기능을 제공합니다.
B28: 전용 함수 | C28: 동작 | D28: 비고 | E28: 지원 버전 (DataSet.maf)
B29: AUD_HIDE_COLUMNS | C29: 지정한 Column 영역을 숨깁니다. 범위를 설정하지 않을 경우 현재 Column을 숨깁니다. | D29: 함수 원형 : AUD_HIDE_COLUMNS(condition As Boolean, [range As range]) As String ＊2022-07-06 | E29: 7.0.300.15
B30: AUD_HIDE_ROWS | C30: 지정한 Row 영역을 숨김니다. 범위를 설정하지 않을 경우 현재 Row를 숨깁니다. | D30: 함수 원형 : AUD_HIDE_ROWS(condition As Boolean, [range As range]) As String ＊2022-07-06 | E30: 7.0.300.15
B31: AUD_IMAGE | C31: 이미지를 셀에 출력합니다. 출력하고자 하는 이미지가 reports/WEB_IMAGES 하위 경로 또는 reports 하위 경로에 존재할 때는 이미지의 파일 명을 입력합니다. 엑셀 내 이미지를 참조할 때는 콜른(:)을 사용합니다. eg. AUD_IMAGE(":Image1") | D31: 함수 원형 : AUD_IMAGE(imageName As Variant) ＊2022-07-06 | E31: 7.0.300.15
B32: AUD_PROPERTY | C32: 지정한 셀에 Client Script API로 접근 가능한 속성을 생성합니다. 해당 값에 접근하는 방법은 아래와 같습니다. var OniGridCellClick = function(sender, args){ if(args.Cell.getProperty(""ITEM1"")){ var arrMsg = []; arrMsg.push(""ITEM 1 = "" + args.Cell.getProperty(""ITEM1"")); arrMsg.push(""ITEM 2 = "" + args.Cell.getProperty(""ITEM2"")); arrMsg.push(""ITEM 3 = "" + args.Cell.getProperty(""ITEM3"")); arrMsg.push(""ITEM 4 = "" + args.Cell.getProperty(""ITEM4"")); alert(arrMsg.join(""\n"")); } };" | D32: 함수 원형 : AUD_PROPERTY(cellText As String, [propName1 As Variant], [propValue1 As Variant], [propName2 As Variant], [propValue2 As Variant]) * 2022-07-19 | E32: 7.0.300.15
B33: AUD_TEMPLATE_BINDING | C33: 지정한 영역을 데이터 바인딩 시의 템플릿으로 사용합니다. 이 함수를 사용한 셀의 Column/Row 값에 1을 더한 범위부터 템플릿화 된 데이터를 출력합니다. formulaRange : 데이터의 필드 명 또는 수식을 지정한 영역을 설정합니다. styleRange : 스타일 영역, 셀의 스타일을 지정할 영역을 설정합니다. alternativeStyleRange : 반복행의 스타일 영역을 설정합니다. | D33: 함수 원형 : AUD_TEMPLATE_BINDING(formulaRange As Variant, styleRange As Variant, [alternativeStyleRange As Variant]) * 2022-07-19 | E33: 7.0.300.15
B34: AUD_CHECK_BOX | C34: 지정한 셀에 CheckBox를 생성합니다. (MX-GRID 에서만 동작 합니다.) text : CheckBox의 텍스트 value : CheckBox의 초기 값 linkRanges : CheckBox의 값이 변경 시 업데이트 할 셀 단일 셀 지정 시 셀의 값을 CheckBox의 값으로 업데이트 합니다. 영역 지정 시 영역 내 CheckBox의 상태를 현재 CheckBox의 상태로 업데이트 합니다. (전체 선택 기능) ststus가 기입되지 않으면 linkRanges 의 모든 값을 CheckBox의 값과 비교하여 동일한 경우 선택 상태가 됩니다. status : CheckBox의 선택 여부를 가져올 값 (0:false, 1:true, -1:mix) | D34: 함수 원형 : AUD_CHECK_BOX(text As Variant, value As Variant, [linkCell As range], [status As Integer]) * 2022-07-19 | E34: 7.0.300.36
B35: AUD_RADIO_BUTTON | C35: 지정한 셀에 RadioButton을 생성합니다. (MX-GRID 에서만 동작 합니다.) text : RadioButton의 텍스트 value : RadioButton의 값 linkCell : RadioButton의 값이 변경될 경우 업데이트 할 셀 해당 셀의 값이 현재 RadioButton의 값과 동일할 경우 체크합니다. | D35: 함수 원형 : AUD_RADIO_BUTTON(text As Variant, value As Variant, [linkCell As range]) * 2022-07-19 | E35: 7.0.300.36
B36: AUD_PROTECT | C36: 지정한 셀을 수정할 수 없도록 잠급니다. range1 : 잠금 대상 셀의 영역 또는 주소값 range2..? : 잠금 대상 셀의 영역 또는 주소값 | D36: 함수 원형 : AUD_PROTECT(range1 As Variant, [range2 As Variant], [range3 As Variant], [range4 As Variant]) As String * 2023-02-08 | E36: 7.0.400.14
B37: AUD_PROTECT_INDIRECT | C37: 지정한 셀을 수정할 수 없도록 잠급니다. range1 : 잠금 대상 셀의 주소값을 가지는 영역 또는 주소값 range2..? : 잠금 대상 셀의 주소값을 가지는 영역 또는 주소값 | D37: 함수 원형 : AUD_PROTECT_INDIRECT(range1 As Variant, [range2 As Variant], [range3 As Variant], [range4 As Variant]) As String * 2023-02-08 | E37: 7.0.400.14
B38: AUD_EXPAND_ROW | C38: 지정한 ROW 영역에 확장/축소 버튼을 생성합니다. isExpand : 확장 상태로 표시할지 여부 range1 : 확장, 축소 대상 Row range2..?: 확장, 축소 대상 Row | D38: 함수 원형 : AUD_EXPAND_ROW(isExpand As Boolean, range1 As Variant, [range2 As Variant], [range3 As Variant]) As String * 2023-02-10 | E38: 7.0.400.14
B39: AUD_EXPAND_COLUMN | C39: 지정한 COLUMN 영역에 확장/축소 버튼을 생성합니다. isExpand : 확장 상태로 표시할지 여부 range1 : 확장, 축소 대상 Column range2..?: 확장, 축소 대상 Column | D39: 함수 원형 : AUD_EXPAND_COLUMN(isExpand As Boolean, range1 As Variant, [range2 As Variant], [range3 As Variant]) As String * 2023-02-10 | E39: 7.0.400.14
B40: AUD_ISMODIFIED | C40: 지정한 범위 내 셀의 수정 여부를 반환합니다. range1 ~ range? : 수정 여부를 점검할 셀 범위 정보 | D40: 함수 원형 : AUD_ISMODIFIED(range1 As Variant, [range2 As Variant], [range3 As Variant], [range4 As Variant]) As String * 2023-03-19 | E40: 7.0.400.24
